Workbook

Sheet CALENDARIO
B33: FASES | N33: FASES
C35: FECHA TENTATIVA DE REVISION | D35: FASE | E35: ACTIVIDADES PARA REVISAR CON CHECKLIST | F35: ESTADO | G35: total | H35: items hechas | I35: items sin hacer | J35: AAR | K35: LLG | L35: MTR | M35: EGB | N35: SMR | O35: EVIDENCIA | P35: CONTENIDO
C36: 46204 | D36: 1 Planeación | E36: Definir pregunta de investigación, objetivos, criterios de inclusión/exclusión y equipo de trabajo. | F36: =_xlfn.PERCENTOF(H36,G36) -> 0.93333333 | G36: =COUNTIF(Checklist!$A:$A,TEXT(CALENDARIO!D36,1)) -> 15 | H36: =G36-I36 -> 14 | I36: =COUNTIFS(Checklist!$A:$A,TEXT(CALENDARIO!D36,1),Checklist!$J:$J,0) -> 1 | J36: =_xlfn.PERCENTOF(COUNTIFS(Checklist!$A:$A,TEXT(CALENDARIO!D36,1),Checklist!$E:$E,TRUE),G36) -> 0.53333333 | K36: =_xlfn.PERCENTOF(COUNTIFS(Checklist!$A:$A,TEXT(CALENDARIO!D36,1),Checklist!$F:$F,TRUE),G36) -> 0.13333333 | L36: =_xlfn.PERCENTOF(COUNTIFS(Checklist!$A:$A,TEXT(CALENDARIO!D36,1),Checklist!$G:$G,TRUE),G36) -> 0.46666667 | M36: =_xlfn.PERCENTOF(COUNTIFS(Checklist!$A:$A,TEXT(CALENDARIO!D36,1),Checklist!$H:$H,TRUE),G36) -> 0 | N36: =_xlfn.PERCENTOF(COUNTIFS(Checklist!$A:$A,TEXT(CALENDARIO!D36,1),Checklist!$I:$I,TRUE),G36) -> 0.33333333 | O36: PROTOCOLO FIRMADO | P36: PROTOCOLO COORDINACION
C37: 46245 | D37: 2 Protocolo | E37: Redactar el protocolo y registrar la revisión si aplica. | F37: =_xlfn.PERCENTOF(H37,G37) -> 1 | G37: =COUNTIF(Checklist!$A:$A,TEXT(CALENDARIO!D37,1)) -> 20 | H37: =G37-I37 -> 20 | I37: =COUNTIFS(Checklist!$A:$A,TEXT(CALENDARIO!D37,1),Checklist!$J:$J,0) -> 0 | J37: =_xlfn.PERCENTOF(COUNTIFS(Checklist!$A:$A,TEXT(CALENDARIO!D37,1),Checklist!$E:$E,TRUE),G37) -> 0.7 | K37: =_xlfn.PERCENTOF(COUNTIFS(Checklist!$A:$A,TEXT(CALENDARIO!D37,1),Checklist!$F:$F,TRUE),G37) -> 0.1 | L37: =_xlfn.PERCENTOF(COUNTIFS(Checklist!$A:$A,TEXT(CALENDARIO!D37,1),Checklist!$G:$G,TRUE),G37) -> 0.9 | M37: =_xlfn.PERCENTOF(COUNTIFS(Checklist!$A:$A,TEXT(CALENDARIO!D37,1),Checklist!$H:$H,TRUE),G37) -> 0 | N37: =_xlfn.PERCENTOF(COUNTIFS(Checklist!$A:$A,TEXT(CALENDARIO!D37,1),Checklist!$I:$I,TRUE),G37) -> 0.1 | O37: C:\Users\estef\OneDrive\PROTOCOL 2.0.pdf | P37: PROTOCOLO EN PROSPERO | Q37: TÍTULO
C38: 46266 | D38: 3 Estrategia de búsqueda | E38: Diseñar ecuaciones de búsqueda, seleccionar bases de datos y probar la estrategia. | F38: =_xlfn.PERCENTOF(H38,G38) -> 0.98148148 | G38: =COUNTIF(Checklist!$A:$A,TEXT(CALENDARIO!D38,1)) -> 54 | H38: =G38-I38 -> 53 | I38: =COUNTIFS(Checklist!$A:$A,TEXT(CALENDARIO!D38,1),Checklist!$J:$J,0) -> 1 | J38: =_xlfn.PERCENTOF(COUNTIFS(Checklist!$A:$A,TEXT(CALENDARIO!D38,1),Checklist!$E:$E,TRUE),G38) -> 0.96296296 | K38: =_xlfn.PERCENTOF(COUNTIFS(Checklist!$A:$A,TEXT(CALENDARIO!D38,1),Checklist!$F:$F,TRUE),G38) -> 0 | L38: =_xlfn.PERCENTOF(COUNTIFS(Checklist!$A:$A,TEXT(CALENDARIO!D38,1),Checklist!$G:$G,TRUE),G38) -> 0.037037037 | M38: =_xlfn.PERCENTOF(COUNTIFS(Checklist!$A:$A,TEXT(CALENDARIO!D38,1),Checklist!$H:$H,TRUE),G38) -> 0 | N38: =_xlfn.PERCENTOF(COUNTIFS(Checklist!$A:$A,TEXT(CALENDARIO!D38,1),Checklist!$I:$I,TRUE),G38) -> 0 | P38: ANEXO ESTRATEGIAS | Q38: ARCHIVOS
C39: 46270 | D39: 4 Búsqueda bibliográfica | E39: Ejecutar búsquedas en bases de datos y otras fuentes, descargar resultados y eliminar duplicados. | F39: =_xlfn.PERCENTOF(H39,G39) -> 1 | G39: =COUNTIF(Checklist!$A:$A,TEXT(CALENDARIO!D39,1)) -> 2 | H39: =G39-I39 -> 2 | I39: =COUNTIFS(Checklist!$A:$A,TEXT(CALENDARIO!D39,1),Checklist!$J:$J,0) -> 0 | J39: =_xlfn.PERCENTOF(COUNTIFS(Checklist!$A:$A,TEXT(CALENDARIO!D39,1),Checklist!$E:$E,TRUE),G39) -> 1 | K39: =_xlfn.PERCENTOF(COUNTIFS(Checklist!$A:$A,TEXT(CALENDARIO!D39,1),Checklist!$F:$F,TRUE),G39) -> 1 | L39: =_xlfn.PERCENTOF(COUNTIFS(Checklist!$A:$A,TEXT(CALENDARIO!D39,1),Checklist!$G:$G,TRUE),G39) -> 0 | M39: =_xlfn.PERCENTOF(COUNTIFS(Checklist!$A:$A,TEXT(CALENDARIO!D39,1),Checklist!$H:$H,TRUE),G39) -> 0 | N39: =_xlfn.PERCENTOF(COUNTIFS(Checklist!$A:$A,TEXT(CALENDARIO!D39,1),Checklist!$I:$I,TRUE),G39) -> 0 | P39: MÉTODOS AVANCE | Q39: INTRODUCCIÓN AVANCE
C40: 46280 | D40: 5 Selección de estudios | E40: Revisar títulos/resúmenes y luego textos completos según criterios de elegibilidad. | F40: =_xlfn.PERCENTOF(H40,G40) -> 0 | G40: =COUNTIF(Checklist!$A:$A,TEXT(CALENDARIO!D40,1)) -> 1 | H40: =G40-I40 -> 0 | I40: =COUNTIFS(Checklist!$A:$A,TEXT(CALENDARIO!D40,1),Checklist!$J:$J,0) -> 1 | J40: =_xlfn.PERCENTOF(COUNTIFS(Checklist!$A:$A,TEXT(CALENDARIO!D40,1),Checklist!$E:$E,TRUE),G40) -> 0 | K40: =_xlfn.PERCENTOF(COUNTIFS(Checklist!$A:$A,TEXT(CALENDARIO!D40,1),Checklist!$F:$F,TRUE),G40) -> 0 | L40: =_xlfn.PERCENTOF(COUNTIFS(Checklist!$A:$A,TEXT(CALENDARIO!D40,1),Checklist!$G:$G,TRUE),G40) -> 0 | M40: =_xlfn.PERCENTOF(COUNTIFS(Checklist!$A:$A,TEXT(CALENDARIO!D40,1),Checklist!$H:$H,TRUE),G40) -> 0 | N40: =_xlfn.PERCENTOF(COUNTIFS(Checklist!$A:$A,TEXT(CALENDARIO!D40,1),Checklist!$I:$I,TRUE),G40) -> 0
C41: 46295 | D41: 6 Extracción de datos | E41: Diseñar formulario, extraer datos y verificar consistencia entre revisores. | F41: =_xlfn.PERCENTOF(H41,G41) -> 0 | G41: =COUNTIF(Checklist!$A:$A,TEXT(CALENDARIO!D41,1)) -> 2 | H41: =G41-I41 -> 0 | I41: =COUNTIFS(Checklist!$A:$A,TEXT(CALENDARIO!D41,1),Checklist!$J:$J,0) -> 2 | J41: =_xlfn.PERCENTOF(COUNTIFS(Checklist!$A:$A,TEXT(CALENDARIO!D41,1),Checklist!$E:$E,TRUE),G41) -> 0 | K41: =_xlfn.PERCENTOF(COUNTIFS(Checklist!$A:$A,TEXT(CALENDARIO!D41,1),Checklist!$F:$F,TRUE),G41) -> 0 | L41: =_xlfn.PERCENTOF(COUNTIFS(Checklist!$A:$A,TEXT(CALENDARIO!D41,1),Checklist!$G:$G,TRUE),G41) -> 0 | M41: =_xlfn.PERCENTOF(COUNTIFS(Checklist!$A:$A,TEXT(CALENDARIO!D41,1),Checklist!$H:$H,TRUE),G41) -> 0 | N41: =_xlfn.PERCENTOF(COUNTIFS(Checklist!$A:$A,TEXT(CALENDARIO!D41,1),Checklist!$I:$I,TRUE),G41) -> 0 | P41: DIAGRAMA DE FLUJO PRISMA 2020
C42: 46310 | D42: 7 Evaluación de calidad | E42: Valorar riesgo de sesgo o calidad metodológica de los estudios incluidos. | F42: =_xlfn.PERCENTOF(H42,G42) -> 0 | G42: =COUNTIF(Checklist!$A:$A,TEXT(CALENDARIO!D42,1)) -> 8 | H42: =G42-I42 -> 0 | I42: =COUNTIFS(Checklist!$A:$A,TEXT(CALENDARIO!D42,1),Checklist!$J:$J,0) -> 8 | J42: =_xlfn.PERCENTOF(COUNTIFS(Checklist!$A:$A,TEXT(CALENDARIO!D42,1),Checklist!$E:$E,TRUE),G42) -> 0 | K42: =_xlfn.PERCENTOF(COUNTIFS(Checklist!$A:$A,TEXT(CALENDARIO!D42,1),Checklist!$F:$F,TRUE),G42) -> 0 | L42: =_xlfn.PERCENTOF(COUNTIFS(Checklist!$A:$A,TEXT(CALENDARIO!D42,1),Checklist!$G:$G,TRUE),G42) -> 0 | M42: =_xlfn.PERCENTOF(COUNTIFS(Checklist!$A:$A,TEXT(CALENDARIO!D42,1),Checklist!$H:$H,TRUE),G42) -> 0 | N42: =_xlfn.PERCENTOF(COUNTIFS(Checklist!$A:$A,TEXT(CALENDARIO!D42,1),Checklist!$I:$I,TRUE),G42) -> 0 | P42: METODOLOGIA | Q42: .
C43: 46325 | D43: 8 Síntesis | E43: Realizar síntesis narrativa Y meta-análisis, según corresponda. | F43: =_xlfn.PERCENTOF(H43,G43) -> 0 | G43: =COUNTIF(Checklist!$A:$A,TEXT(CALENDARIO!D43,1)) -> 18 | H43: =G43-I43 -> 0 | I43: =COUNTIFS(Checklist!$A:$A,TEXT(CALENDARIO!D43,1),Checklist!$J:$J,0) -> 18 | J43: =_xlfn.PERCENTOF(COUNTIFS(Checklist!$A:$A,TEXT(CALENDARIO!D43,1),Checklist!$E:$E,TRUE),G43) -> 0 | K43: =_xlfn.PERCENTOF(COUNTIFS(Checklist!$A:$A,TEXT(CALENDARIO!D43,1),Checklist!$F:$F,TRUE),G43) -> 0 | L43: =_xlfn.PERCENTOF(COUNTIFS(Checklist!$A:$A,TEXT(CALENDARIO!D43,1),Checklist!$G:$G,TRUE),G43) -> 0 | M43: =_xlfn.PERCENTOF(COUNTIFS(Checklist!$A:$A,TEXT(CALENDARIO!D43,1),Checklist!$H:$H,TRUE),G43) -> 0 | N43: =_xlfn.PERCENTOF(COUNTIFS(Checklist!$A:$A,TEXT(CALENDARIO!D43,1),Checklist!$I:$I,TRUE),G43) -> 0 | P43: RESULTADOS
C44: 46341 | D44: 9 Redacción | E44: Escribir resultados, discusión, conclusiones y preparar figuras/tablas. | F44: =_xlfn.PERCENTOF(H44,G44) -> 0 | G44: =COUNTIF(Checklist!$A:$A,TEXT(CALENDARIO!D44,1)) -> 12 | H44: =G44-I44 -> 0 | I44: =COUNTIFS(Checklist!$A:$A,TEXT(CALENDARIO!D44,1),Checklist!$J:$J,0) -> 12 | J44: =_xlfn.PERCENTOF(COUNTIFS(Checklist!$A:$A,TEXT(CALENDARIO!D44,1),Checklist!$E:$E,TRUE),G44) -> 0 | K44: =_xlfn.PERCENTOF(COUNTIFS(Checklist!$A:$A,TEXT(CALENDARIO!D44,1),Checklist!$F:$F,TRUE),G44) -> 0 | L44: =_xlfn.PERCENTOF(COUNTIFS(Checklist!$A:$A,TEXT(CALENDARIO!D44,1),Checklist!$G:$G,TRUE),G44) -> 0 | M44: =_xlfn.PERCENTOF(COUNTIFS(Checklist!$A:$A,TEXT(CALENDARIO!D44,1),Checklist!$H:$H,TRUE),G44) -> 0 | N44: =_xlfn.PERCENTOF(COUNTIFS(Checklist!$A:$A,TEXT(CALENDARIO!D44,1),Checklist!$I:$I,TRUE),G44) -> 0 | P44: DISCUSIÓN | Q44: FINANCIAMIENTO
C45: 46356 | D45: 10 Revisión final | E45: Correcciones de coautores, ajuste al formato de revista y envío. | F45: =_xlfn.PERCENTOF(H45,G45) -> 0 | G45: =COUNTIF(Checklist!$A:$A,TEXT(CALENDARIO!D45,1)) -> 2 | H45: =G45-I45 -> 0 | I45: =COUNTIFS(Checklist!$A:$A,TEXT(CALENDARIO!D45,1),Checklist!$J:$J,0) -> 2 | J45: =_xlfn.PERCENTOF(COUNTIFS(Checklist!$A:$A,TEXT(CALENDARIO!D45,1),Checklist!$E:$E,TRUE),G45) -> 0 | K45: =_xlfn.PERCENTOF(COUNTIFS(Checklist!$A:$A,TEXT(CALENDARIO!D45,1),Checklist!$F:$F,TRUE),G45) -> 0 | L45: =_xlfn.PERCENTOF(COUNTIFS(Checklist!$A:$A,TEXT(CALENDARIO!D45,1),Checklist!$G:$G,TRUE),G45) -> 0 | M45: =_xlfn.PERCENTOF(COUNTIFS(Checklist!$A:$A,TEXT(CALENDARIO!D45,1),Checklist!$H:$H,TRUE),G45) -> 0 | N45: =_xlfn.PERCENTOF(COUNTIFS(Checklist!$A:$A,TEXT(CALENDARIO!D45,1),Checklist!$I:$I,TRUE),G45) -> 0 | P45: RESUMEN
F46: =_xlfn.PERCENTOF(H46,G46) -> 0.6641791 | G46: =SUM(G36:G45) -> 134 | H46: =SUM(H36:H45) -> 89 | I46: =SUM(I36:I45) -> 45 | J46: =_xlfn.PERCENTOF(J36:J45,$G46) -> 0.023852957 | K46: =_xlfn.PERCENTOF(K36:K45,$G46) -> 0.0092039801 | L46: =_xlfn.PERCENTOF(L36:L45,$G46) -> 0.010475401 | M46: =_xlfn.PERCENTOF(M36:M45,$G46) -> 0 | N46: =_xlfn.PERCENTOF(N36:N45,$G46) -> 0.0032338308

Sheet Hoja2
A3: Cuenta de STATUS | B3: Etiquetas de columna
A4: Etiquetas de fila | B4: 0 | C4: 1 | D4: X | E4: Total general
A5: 1 Planeación | B5: 13 | C5: 2 | E5: 15
A6: 10 Revisión final | B6: 2 | E6: 2
A7: 2 Protocolo | B7: 25 | E7: 25
A8: 3 Estrategia de búsqueda | B8: 54 | E8: 54
A9: 4 Búsqueda bibliográfica | B9: 2 | E9: 2
A10: 5 Selección de estudios | B10: 1 | E10: 1
A11: 6 Extracción de datos | B11: 2 | E11: 2
A12: 7 Evaluación de calidad | B12: 8 | E12: 8
A13: 8 Síntesis | B13: 18 | E13: 18
A14: 9 Redacción | B14: 10 | E14: 10
A15: (en blanco) | D15: 17 | E15: 17
A16: Total general | B16: 135 | C16: 2 | D16: 17 | E16: 154

Sheet Checklist
A1: FASE | B1: Sección/tema | C1: ítem # | D1: ASPECTO A REVISAR | E1: AAR | F1: LLG | G1: MTR | H1: EGB | I1: SMR | J1: STATUS | K1: NOTAS
C2: TITLE | D2: .Tabla 2.- PRISMA 2020 Lista de verificación | J2: X
A3: 2 Protocolo | B3: Titulo | C3: 1 | D3: Identificar la publicación como revisión sistemática, | E3: TRUE | F3: TRUE | G3: FALSE | H3: FALSE | I3: FALSE | J3: =COUNTIF(E3:I3,(NOT(FALSE))) -> 2
C4: RESUMEN | J4: X
A5: 9 Redacción | B5: Resumen | C5: 2 | D5: Consulte la lista de comprobación PRISMA 2020 para resúmenes (Tabla 2). | E5: FALSE | F5: FALSE | G5: FALSE | H5: FALSE | I5: FALSE | J5: =COUNTIF(E5:I5,(NOT(FALSE))) -> 0
C6: INTRODUCTION | J6: X
A7: 9 Redacción | B7: Justificación | C7: 3 | D7: Describa la justificación de la revisión en el contexto de los conocimientos existentes. | E7: FALSE | F7: FALSE | G7: FALSE | H7: FALSE | I7: FALSE | J7: =COUNTIF(E7:I7,(NOT(FALSE))) -> 0
A8: 9 Redacción | B8: Objetivos | C8: 4 | D8: Proporcione una declaración explícita de los objetivos o preguntas que la revisión desea contestar. | E8: FALSE | F8: FALSE | G8: FALSE | H8: FALSE | I8: FALSE | J8: =COUNTIF(E8:I8,(NOT(FALSE))) -> 0
C9: METODOS | J9: X
A10: 3 Estrategia de búsqueda | B10: Criterios de elegibilidad | C10: 5 | D10: Especifique los criterios de inclusión y exclusión para la revisión y cómo se agruparon los estudios para la síntesis. | E10: TRUE | F10: FALSE | G10: FALSE | H10: FALSE | I10: FALSE | J10: =COUNTIF(E10:I10,(NOT(FALSE))) -> 1
A11: 4 Búsqueda bibliográfica | B11: Fuentes de información | C11: 6 | D11: Especifique todas las bases de datos, registros, sitios web, organizaciones, listas de referencia y otras fuentes buscadas o consultadas para identificar estudios. Especifique la fecha en la que se buscó o consultó por última vez cada fuente. | E11: TRUE | F11: TRUE | G11: FALSE | H11: FALSE | I11: FALSE | J11: =COUNTIF(E11:I11,(NOT(FALSE))) -> 2
A12: 3 Estrategia de búsqueda | B12: Estrategia de búsqueda | C12: 7 | D12: Presentar las estrategias de búsqueda completas para todas las bases de datos, registros y sitios web, incluidos los filtros y los límites utilizados. | E12: TRUE | F12: FALSE | G12: FALSE | H12: FALSE | I12: FALSE | J12: =COUNTIF(E12:I12,(NOT(FALSE))) -> 1
A13: 5 Selección de estudios | B13: Proceso de selección | C13: 8 | D13: Especifique los métodos utilizados para decidir si un estudio cumplía los criterios para la inclusión de la revisión, incluidos cuántos revisores examinaron cada registro y cada informe recuperado, si trabajaron de forma independiente y, si procede, los detalles de las herramientas de automatización utilizadas en el proceso. | E13: FALSE | F13: FALSE | G13: FALSE | H13: FALSE | I13: FALSE | J13: =COUNTIF(E13:I13,(NOT(FALSE))) -> 0
A14: 6 Extracción de datos | B14: Proceso de recopilación de datos | C14: 9 | D14: Especifique los métodos utilizados para recopilar los datos de los estudios, incluido el número de revisores que recopilaron datos de cada informe, si trabajaron de forma independiente, los procesos para obtener o confirmar datos de los investigadores del estudio y, si procede, los detalles de las herramientas de automatización utilizadas en el proceso. | E14: FALSE | F14: FALSE | G14: FALSE | H14: FALSE | I14: FALSE | J14: =COUNTIF(E14:I14,(NOT(FALSE))) -> 0
A15: 6 Extracción de datos | B15: Lista de datos | C15: 10a | D15: Enumerar y definir todos los desenlaces (outcomes) para los cuales se buscaron datos. Especifique si se buscaron todos los resultados admitidos por cada desenlace (outcome) en cada estudio (por ejemplo, para todas las medidas, puntos de tiempo, análisis) y, si no, los métodos utilizados para decidir qué resultados recopilar. | E15: FALSE | F15: FALSE | G15: FALSE | H15: FALSE | I15: FALSE | J15: =COUNTIF(E15:I15,(NOT(FALSE))) -> 0
A16: 8 Síntesis | C16: 10b | D16: Enumerar y definir todas las demás variables para las cuales se buscaron datos (por ejemplo, características de participante e intervención, fuentes de financiación). Describa cualquier asunción hecha sobre cualquier información que falte o no esté clara. | E16: FALSE | F16: FALSE | G16: FALSE | H16: FALSE | I16: FALSE | J16: =COUNTIF(E16:I16,(NOT(FALSE))) -> 0
A17: 7 Evaluación de calidad | B17: Estudio y valoración del riesgo de sesgo | C17: 11 | D17: Especifique los métodos utilizados para evaluar el riesgo de sesgo en los estudios incluidos, incluidos los detalles de las herramientas utilizadas, cuántos revisores evaluaron cada estudio y si trabajaron de forma independiente y, si procede, los detalles de las herramientas de automatización utilizadas en el proceso. | E17: FALSE | F17: FALSE | G17: FALSE | H17: FALSE | I17: FALSE | J17: =COUNTIF(E17:I17,(NOT(FALSE))) -> 0
A18: 7 Evaluación de calidad | B18: Medidas de efecto | C18: 12 | D18: Especifique para cada resultado como se midió el efecto (por ejemplo, riesgo relativo, diferencia de medias) utilizadas en la síntesis o presentación de resultados. | E18: FALSE | F18: FALSE | G18: FALSE | H18: FALSE | I18: FALSE | J18: =COUNTIF(E18:I18,(NOT(FALSE))) -> 0
A19: 8 Síntesis | B19: Métodos de síntesis | C19: 13a | D19: Describa los procesos utilizados para decidir qué estudios eran elegibles para cada síntesis. (por ejemplo, tabular las características de la intervención del estudio y comparar con los grupos planificados para cada síntesis (ítem #5)). | E19: FALSE | F19: FALSE | G19: FALSE | H19: FALSE | I19: FALSE | J19: =COUNTIF(E19:I19,(NOT(FALSE))) -> 0
A20: 8 Síntesis | C20: 13b | D20: Describir los métodos necesarios para preparar los datos para la presentación o síntesis, como el manejo de las estadísticas de resumen que faltan o las conversiones de datos. | E20: FALSE | F20: FALSE | G20: FALSE | H20: FALSE | I20: FALSE | J20: =COUNTIF(E20:I20,(NOT(FALSE))) -> 0
A21: 8 Síntesis | C21: 13c | D21: Describir cualquier método utilizado para tabular o mostrar visualmente los resultados de estudios individuales y síntesis. | E21: FALSE | F21: FALSE | G21: FALSE | H21: FALSE | I21: FALSE | J21: =COUNTIF(E21:I21,(NOT(FALSE))) -> 0
A22: 8 Síntesis | C22: 13d | D22: Describir los métodos utilizados para sintetizar resultados y proporcionar justificación para las opciones. Si se realizó un metanálisis, describa el modelo (s), el método(s) para identificar la presencia y el alcance de la heterogeneidad estadística y paquete(s) de software utilizados. | E22: FALSE | F22: FALSE | G22: FALSE | H22: FALSE | I22: FALSE | J22: =COUNTIF(E22:I22,(NOT(FALSE))) -> 0
A23: 8 Síntesis | C23: 13e | D23: Describa los métodos utilizados para explorar las posibles causas de la heterogeneidad entre los resultados del estudio (por ejemplo análisis de subgrupos, meta-regresión) | E23: FALSE | F23: FALSE | G23: FALSE | H23: FALSE | I23: FALSE | J23: =COUNTIF(E23:I23,(NOT(FALSE))) -> 0
A24: 8 Síntesis | C24: 13f | D24: Describir los análisis de sensibilidad realizados para evaluar la fortaleza de los resultados sintetizados. | E24: FALSE | F24: FALSE | G24: FALSE | H24: FALSE | I24: FALSE | J24: =COUNTIF(E24:I24,(NOT(FALSE))) -> 0
A25: 7 Evaluación de calidad | B25: Informar de la evaluación del sesgo | C25: 14 | D25: Describa cualquier método utilizado para evaluar el riesgo de sesgo debido a la falta de resultados en una síntesis (derivada de sesgos de notificación). | E25: FALSE | F25: FALSE | G25: FALSE | H25: FALSE | I25: FALSE | J25: =COUNTIF(E25:I25,(NOT(FALSE))) -> 0
A26: 7 Evaluación de calidad | B26: Evaluación de la certeza | C26: 15 | D26: Describa cualquier método utilizado para evaluar la certeza (o confianza) en el cuerpo de evidencia para un desenlace. | E26: FALSE | F26: FALSE | G26: FALSE | H26: FALSE | I26: FALSE | J26: =COUNTIF(E26:I26,(NOT(FALSE))) -> 0
C27: RESULTADOS | J27: X
A28: 8 Síntesis | B28: Selección de los estudios | C28: 16a | D28: Describa los resultados del proceso de búsqueda y selección, desde el número de registros identificados en la búsqueda hasta el número de estudios incluidos en la revisión, idealmente utilizando un diagrama de flujo (consulte la figura 1). | E28: FALSE | F28: FALSE | G28: FALSE | H28: FALSE | I28: FALSE | J28: =COUNTIF(E28:I28,(NOT(FALSE))) -> 0
A29: 8 Síntesis | C29: 16b | D29: Cite los estudios que parece que cumplieran muchos criterios de inclusión y explique por qué fueron excluidos. | E29: FALSE | F29: FALSE | G29: FALSE | H29: FALSE | I29: FALSE | J29: =COUNTIF(E29:I29,(NOT(FALSE))) -> 0
A30: 8 Síntesis | B30: Características del estudio | C30: 17 | D30: Cite cada estudio incluido y muestre sus características. | E30: FALSE | F30: FALSE | G30: FALSE | H30: FALSE | I30: FALSE | J30: =COUNTIF(E30:I30,(NOT(FALSE))) -> 0
A31: 7 Evaluación de calidad | B31: Riesgo de sesgo en los estudios | C31: 18 | D31: Presente la evaluación del riesgo de sesgo para cada estudio que se incluido en la revisión. | E31: FALSE | F31: FALSE | G31: FALSE | H31: FALSE | I31: FALSE | J31: =COUNTIF(E31:I31,(NOT(FALSE))) -> 0
A32: 8 Síntesis | B32: Resultados de estudios individuales | C32: 19 | D32: Para los resultados de cada estudio: a) estadísticas resumidas para cada grupo (cuando proceda) y b) una estimación de efectos y su precisión (por ejemplo, intervalo confianza/intervalo creíble), idealmente utilizando tablas o gráficas estructuradas. | E32: FALSE | F32: FALSE | G32: FALSE | H32: FALSE | I32: FALSE | J32: =COUNTIF(E32:I32,(NOT(FALSE))) -> 0
A33: 8 Síntesis | B33: Resultados de la síntesis | C33: 20a | D33: Para cada combinación o síntesis, resuma brevemente las características y el riesgo de sesgo entre los estudios. | E33: FALSE | F33: FALSE | G33: FALSE | H33: FALSE | I33: FALSE | J33: =COUNTIF(E33:I33,(NOT(FALSE))) -> 0
A34: 8 Síntesis | C34: 20b | D34: Presente los resultados de todas las combinaciones o síntesis estadísticas realizadas. Si se realizó un metanálisis, presente para cada uno un resumen de la estimación y su precisión (por ejemplo. confianza/intervalo creíble) y medidas estadísticas de heterogeneidad. Si compara grupos, describa la dirección del efecto. | E34: FALSE | F34: FALSE | G34: FALSE | H34: FALSE | I34: FALSE | J34: =COUNTIF(E34:I34,(NOT(FALSE))) -> 0
A35: 8 Síntesis | C35: 20c | D35: Presente resultados de toda la investigación de posibles causas de heterogeneidad entre los resultados del estudio. | E35: FALSE | F35: FALSE | G35: FALSE | H35: FALSE | I35: FALSE | J35: =COUNTIF(E35:I35,(NOT(FALSE))) -> 0
A36: 8 Síntesis | C36: 20d | D36: Presente los resultados de todos los análisis de sensibilidad realizados para evaluar la solidez de los resultados combinados. | E36: FALSE | F36: FALSE | G36: FALSE | H36: FALSE | I36: FALSE | J36: =COUNTIF(E36:I36,(NOT(FALSE))) -> 0
A37: 7 Evaluación de calidad | B37: Reportar sesgos | C37: 21 | D37: Evaluaciones de los riesgos de sesgo debido a la falta de resultados (derivados de sesgos de notificación) para cada combinación evaluada. | E37: FALSE | F37: FALSE | G37: FALSE | H37: FALSE | I37: FALSE | J37: =COUNTIF(E37:I37,(NOT(FALSE))) -> 0
A38: 7 Evaluación de calidad | B38: Certeza de la evidencia | C38: 22 | D38: Proporcione evaluaciones de certeza (o confianza) en la evidencia de cada resultado evaluado. | E38: FALSE | F38: FALSE | G38: FALSE | H38: FALSE | I38: FALSE | J38: =COUNTIF(E38:I38,(NOT(FALSE))) -> 0
C39: DISCUSI0N | J39: X
A40: 9 Redacción | B40: Discusión | C40: 23a | D40: Proporcionar una interpretación general de los resultados en el contexto de otras pruebas. | E40: FALSE | F40: FALSE | G40: FALSE | H40: FALSE | I40: FALSE | J40: =COUNTIF(E40:I40,(NOT(FALSE))) -> 0
...

Sheet Hoja3
F7: ESTADO | G7: NO EMPEZADO | H7: EN PROCESO | I7: FINALIZADO | J7: NOTAS ADICIONALES
C9: Sección/Tema | D9: Ítem | E9: Elemento de la lista de verificación | F9: ESTADO | G9: fecha
C10: PROTOCOLO | D10: 0 | E10: protocol 2.0 | F10: FINALIZADO | G10: 46266
C11: TÍTULO | D11: 1 | E11: Identificar el documento como revisión sistemática, metaanálisis o ambos. | F11: EN PROCESO | G11: 46325
C12: RESUMEN | D12: 2 | E12: Presentar un resumen estructurado que incluya antecedentes, objetivos, fuentes, criterios, métodos, resultados, limitaciones y conclusiones. | F12: NO EMPEZADO | G12: 46325
C13: INTRODUCCIÓN | D13: 3 a 4 | E13: Explicar la justificación en el contexto del conocimiento actual definir los objetivos según PICOS: población, intervención, comparador, desenlace y diseño. | F13: EN PROCESO | G13: 46280
C14: MÉTODOS | D14: 5 a 16 | E14: Describir protocolo y registro, criterios de elegibilidad, fuentes de información, estrategia de búsqueda, selección de estudios, recolección y elementos de datos, evaluación del riesgo de sesgo, medidas de resumen, síntesis de resultados y análisis adicionales. | F14: EN PROCESO | G14: 46295
C15: RESULTADOS | D15: 17 a 23 | E15: Presentar la selección y características de los estudios, el riesgo de sesgo, los resultados individuales, la síntesis, los sesgos de notificación y los análisis adicionales. | F15: EN PROCESO | G15: 46310
C16: DISCUSIÓN | D16: 24 a 26 | E16: Resumir la evidencia, discutir las limitaciones y presentar las conclusiones. | F16: NO EMPEZADO | G16: 46325
C17: FINANCIAMIENTO | D17: 27 | E17: Indicar las fuentes de financiamiento y el papel de los financiadores.
C21: FECHA TENTATIVA DE REVISION | D21: FASE | E21: ACTIVIDADES PARA REVISAR CON CHECKLIST | F21: ESTADO | G21: PROGRESO | H21: Columna1
C22: 46235 | D22: 1 Planeación | E22: Definir pregunta de investigación, objetivos, criterios de inclusión/exclusión y equipo de trabajo. | F22: TERMINADO | G22: =COUNTIFS(Checklist!J:J,"<>0",Checklist!A:A,Tabla1[[#This Row],[FASE]],Checklist!J:J,"0") -> 0
C23: 46245 | D23: 2 Protocolo | E23: Redactar el protocolo y registrar la revisión si aplica. | F23: TERMINADO
C24: 46266 | D24: 3 Estrategia de búsqueda | E24: Diseñar ecuaciones de búsqueda, seleccionar bases de datos y probar la estrategia. | F24: TERMINADO
C25: 46268 | D25: 4 Búsqueda bibliográfica | E25: Ejecutar búsquedas en bases de datos y otras fuentes, descargar resultados y eliminar duplicados. | F25: EN PROCESO
C26: 46280 | D26: 5 Selección de estudios | E26: Revisar títulos/resúmenes y luego textos completos según criterios de elegibilidad.
C27: 46295 | D27: 6 Extracción de datos | E27: Diseñar formulario, extraer datos y verificar consistencia entre revisores.
C28: 46310 | D28: 7 Evaluación de calidad | E28: Valorar riesgo de sesgo o calidad metodológica de los estudios incluidos.
C29: 46325 | D29: 8 Síntesis | E29: Realizar síntesis narrativa Y meta-análisis, según corresponda.
C30: 46341 | D30: 9 Redacción | E30: Escribir resultados, discusión, conclusiones y preparar figuras/tablas.
C31: 46356 | D31: 10 Revisión final | E31: Correcciones de coautores, ajuste al formato de revista y envío.

Sheet SeccinTema-tem-Checklistitem.
E1: Miss Andrea Estefania Aranda Rosas | F1: Mr Leandro Jesus Lozano Garcia | G1: Professor Miguel Angel Trejo-Rodriguez | H1: Professor Erik Gonzalez-Ballesteros | I1: Dr Sandra Martinez Robles
E2: AUTOR, REVISOR | F2: AUTOR, REVISOR | G2: ASESOR, AUTOR | H2: ASESOR | I2: ASESOR
A3: fecha | B3: Sección/Tema | C3: Ítem | D3: Elemento de la lista de verificación | E3: AAR | F3: LLG | G3: MTR | H3: EGB | I3: SMR
A4: 46266 | B4: PROTOCOLO | C4: 0 | D4: protocol 2.0 | E4: TRUE | F4: FALSE | G4: TRUE | H4: FALSE | I4: TRUE
A5: 46325 | B5: TÍTULO | C5: 1 | D5: Identificar el documento como revisión sistemática, metaanálisis o ambos. | E5: FALSE | F5: FALSE | G5: TRUE | H5: TRUE | I5: TRUE
A6: 46325 | B6: RESUMEN | C6: 2 | D6: Presentar un resumen estructurado que incluya antecedentes, objetivos, fuentes, criterios, métodos, resultados, limitaciones y conclusiones. | E6: FALSE | F6: FALSE | G6: FALSE | H6: FALSE | I6: FALSE
A7: 46280 | B7: INTRODUCCIÓN | C7: 3 a 4 | D7: Explicar la justificación en el contexto del conocimiento actual definir los objetivos según PICOS: población, intervención, comparador, desenlace y diseño. | E7: FALSE | F7: FALSE | G7: FALSE | H7: FALSE | I7: FALSE
A8: 46295 | B8: MÉTODOS | C8: 5 a 16 | D8: Describir protocolo y registro, criterios de elegibilidad, fuentes de información, estrategia de búsqueda, selección de estudios, recolección y elementos de datos, evaluación del riesgo de sesgo, medidas de resumen, síntesis de resultados y análisis adicionales. | E8: FALSE | F8: FALSE | G8: FALSE | H8: FALSE | I8: FALSE
A9: 46310 | B9: RESULTADOS | C9: 17 a 23 | D9: Presentar la selección y características de los estudios, el riesgo de sesgo, los resultados individuales, la síntesis, los sesgos de notificación y los análisis adicionales. | E9: FALSE | F9: FALSE | G9: FALSE | H9: FALSE | I9: FALSE
A10: 46325 | B10: DISCUSIÓN | C10: 24 a 26 | D10: Resumir la evidencia, discutir las limitaciones y presentar las conclusiones. | E10: FALSE | F10: FALSE | G10: FALSE | H10: FALSE | I10: FALSE
B11: FINANCIAMIENTO | C11: 27 | D11: Indicar las fuentes de financiamiento y el papel de los financiadores. | E11: FALSE | F11: FALSE | G11: FALSE | H11: FALSE | I11: FALSE
A16: Fase | B16: Duración estimada | D16: Actividades | E16: AAR | F16: LLG | G16: MTR | H16: EGB | I16: SMR
A17: 1. Planeación | B17: Semanas 1–2 | D17: Definir pregunta de investigación, objetivos, criterios de inclusión/exclusión y equipo de trabajo. | E17: TRUE | F17: TRUE | G17: TRUE | H17: TRUE | I17: TRUE
A18: 2. Protocolo | B18: Semanas 3–4 | D18: Redactar el protocolo y registrar la revisión si aplica. | E18: TRUE | F18: FALSE | G18: TRUE | H18: FALSE | I18: FALSE
A19: 3. Estrategia de búsqueda | B19: Semanas 5–6 | D19: Diseñar ecuaciones de búsqueda, seleccionar bases de datos y probar la estrategia. | E19: TRUE | F19: FALSE | G19: TRUE | H19: FALSE | I19: FALSE
A20: 4. Búsqueda bibliográfica | B20: Semanas 7–8 | D20: Ejecutar búsquedas en bases de datos y otras fuentes, descargar resultados y eliminar duplicados. | E20: TRUE | F20: FALSE | G20: TRUE | H20: FALSE | I20: FALSE
A21: 5. Selección de estudios | B21: Semanas 9–12 | D21: Revisar títulos/resúmenes y luego textos completos según criterios de elegibilidad. | E21: FALSE | F21: FALSE | G21: FALSE | H21: FALSE | I21: FALSE
A22: 6. Extracción de datos | B22: Semanas 13–16 | D22: Diseñar formulario, extraer datos y verificar consistencia entre revisores. | E22: TRUE | F22: FALSE | G22: FALSE | H22: FALSE | I22: FALSE
A23: 7. Evaluación de calidad | B23: Semanas 15–17 | D23: Valorar riesgo de sesgo o calidad metodológica de los estudios incluidos. | E23: FALSE | F23: FALSE | G23: FALSE | H23: FALSE | I23: FALSE
A24: 8. Síntesis | B24: Semanas 18–20 | D24: Realizar síntesis narrativa o meta-análisis, según corresponda. | E24: FALSE | F24: FALSE | G24: FALSE | H24: FALSE | I24: FALSE
A25: 9. Redacción | B25: Semanas 21–24 | D25: Escribir resultados, discusión, conclusiones y preparar figuras/tablas. | E25: FALSE | F25: FALSE | G25: FALSE | H25: FALSE | I25: FALSE
A26: 10. Revisión final | B26: Semanas 25–26 | D26: Correcciones de coautores, ajuste al formato de revista y envío. | E26: FALSE | F26: FALSE | G26: FALSE | H26: FALSE | I26: FALSE
